Workbook

Sheet Read me
A1: Sheriff Sale Underwriting Model, Philadelphia Nov 3 2026
A3: How to use
A4: 1. Put each property on the Deals sheet (yellow cells). ARV and rent come from the comps work; liens and lien position from the title check.
A5: 2. Change any assumption on the Assumptions sheet. Every number in the model reads from there.
A6: 3. Underwriting shows the best exit, the highest bid that still hits the target, and the cash it takes.
A7: 4. Bid Ladder shows profit and return at a range of bids. Portfolio adds up the cash against the $1M cap.
A9: How the max bid is found
A10: Flip: highest bid where ARV minus selling costs, rehab, carry, legal, possession, liens, fees and the 1.5% premium still leaves the $50k target.
A11: Value-add hold: highest bid where stabilized NOI divided by all-in cost is at least 12% (yield on cost, unlevered). Switch Assumptions > 'Value-add: measure' to Cash-on-cash to test levered cash flow after a refi on the cash left in instead.
A12: Wholesale: bid you could pay and still assign the bid to a flipper who needs 15% of ARV, keeping a $15k fee. Shown as an alternative only.
A13: Teardown: new units sold at the per-unit value you enter, less demo, build, soft costs and carry, with a 15% developer margin.
A15: Sale rules built in
... A22: Risk the sale is pulled, set aside or voided by bankruptcy (cash is tied up but returned). IRS 120-day redemption. Opportunity cost of cash. Price changes during the long hold.

Sheet Assumptions
A1: Assumptions (yellow cells are inputs; every sheet reads from here)
A3: Assumption | B3: Value | C3: Note
A4: Targets (ryan's buy box)
A5: Flip: minimum profit | B5: 50000 | C5: ryan's target: $50k profit per flip
A6: Flip: minimum annualized return on cash (0 = off) | B6: 0.15 | C6: Second test so big-ticket flips can't pass on $50k alone over a 2-year hold. Simple annualized: profit / peak cash / years held. ryan confirmed 15% on Oct 20
A7: Flip: all-in cost ceiling (bid + rehab + costs) | B7: 300000 | C7: Ideal box. A deal over this is flagged, not excluded
A8: Value-add: target annual return | B8: 0.12 | C8: ryan's target: 12%
A9: Value-add: measure the 12% is tested on | B9: Yield on cost | C9: Yield on cost = stabilized NOI / all-in cost (unlevered). Cash-on-cash = cash flow after refi debt service / cash left in after refi
A10: Total cash available | B10: 1000000 | C10: ryan's maximum cash
A11: Sale terms (Philadelphia Sheriff, Nov 3 2026)
A12: Buyer's premium | B12: 0.015 | C12: 1.5% of price, paid with the 10% down
A13: Down payment due Nov 4 | B13: 0.1 | C13: 10% + premium by 5 PM Nov 4; $10k deposit counts toward it
A14: Sheriff / Bid4Assets fees per lot | B14: 70 | C14: $35 processing + $35 balance fee
A15: Bidder deposit (credited to the Nov 4 down payment) | B15: 5000 | C15: $5,000 + $35 fee, received by Bid4Assets 4 PM ET Oct 27 (wire, certified check, money order)
A16: Realty transfer tax taken out of the bid | B16: 0.04578 | C16: Sheriff pays it from the price, before city claims
A17: Sheriff costs paid from the bid before city claims | B17: 2500 | C17: Poundage, advertising, service. Estimate; check the distribution schedule
A18: Title insurance and recording after deed | B18: 2000 | C18: Transfer tax on purchase is paid from the bid, so $0 here
A19: Legal: petition to compel deed / docket review | B19: 2500 | C19: Deeds running 12+ months; budget counsel on every lot
A20: Timeline (months)
A21: Sale to recorded deed | B21: 12 | C21: Rules research: 9-15 months, base 12
A22: Deed to vacant possession if occupied | B22: 5 | C22: Ejectment 3-6 months if uncontested
A23: Treat unknown occupancy as occupied? (Y/N) | B23: Y | C23: Conservative default until the drive-by
A24: Flip: list to closed sale | B24: 3
A25: Hold: rehab done to rent starts | B25: 2
A26: Carry while waiting / rehabbing (per month)
A27: Real estate tax rate (of OPA market value) | B27: 0.013998 | C27: Philadelphia 2026
A28: Vacant-property insurance | B28: 175
A29: Securing, lawn, trash, inspections | B29: 150 | C29: Includes L&I vacant-property upkeep
A30: Utilities | B30: 100
A31: Condo/HOA arrears that survive (months) | B31: 6 | C31: 68 Pa.C.S. 3315 / 5315
A32: Possession
A33: Possession cost if occupied | B33: 5000 | C33: Ejectment counsel + $325 writ + lockout/trash-out, or cash for keys
A34: Rehab (interior unseen)
A35: Blind-interior contingency on $/sf budget | B35: 0.2 | C35: No interior access before purchase
A36: Fixed allowance per property | B36: 10000 | C36: Cleanout, permits, lead/asbestos test, utility reconnects, systems surprises
A37: Flip exit
A38: Listing + buyer agent commission | B38: 0.05
A39: Seller share of realty transfer tax | B39: 0.02289 | C39: Half of 4.578%
A40: Other seller closing costs | B40: 0.01
A41: Buyer concessions / price cuts | B41: 0.01
...

Sheet Deals
A1: Property inputs. One row per property; yellow cells are inputs. Rows flow automatically to Underwriting, Bid Ladder and Portfolio.
A2: Auction ID | B2: Address | C2: ZIP | D2: Opening bid | E2: Judgment / debt | F2: Plaintiff lien position | G2: Building sf | H2: Lot sf | I2: Year built | J2: Units (after rehab) | K2: OPA market value | L2: As-is value | M2: ARV | N2: Market rent / mo (all units) | O2: Rehab scope | P2: Exterior / known adders | Q2: Occupancy | R2: Surviving liens not covered by bid | S2: City claims owed (RE tax, water/sewer, other) | T2: Condo/HOA dues / mo | U2: Teardown: units possible | V2: Teardown: new-build sf | W2: Teardown: sale value / unit | X2: Data status / notes
A3: 1311511-0 | B3: 0 Prior screen (ARV 695k, Medium, occupied) | C3: 19125 | D3: 27200 | E3: 329601 | F3: 1st | G3: 1728 | H3: 1113 | I3: 1925 | J3: 1 | K3: 409100 | L3: 452000 | M3: 695000 | N3: 2750 | O3: Medium | P3: 0 | Q3: Occupied | R3: 2500 | X3: 12 W Palmer deep dive scenario
A4: 1311511-1 | B4: 1 Base: ARV 675k, Heavy (stalled 2019 demo), vacant | C4: 19125 | D4: 27200 | E4: 329601 | F4: 1st | G4: 1728 | H4: 1113 | I4: 1925 | J4: 1 | K4: 409100 | L4: 380000 | M4: 675000 | N4: 3200 | O4: Heavy | P4: 0 | Q4: Vacant | R4: 2500 | X4: 12 W Palmer deep dive scenario
A5: 1311511-2 | B5: 2 Base but occupied (squatter/holdover) | C5: 19125 | D5: 27200 | E5: 329601 | F5: 1st | G5: 1728 | H5: 1113 | I5: 1925 | J5: 1 | K5: 409100 | L5: 380000 | M5: 675000 | N5: 3200 | O5: Heavy | P5: 0 | Q5: Occupied | R5: 2500 | X5: 12 W Palmer deep dive scenario
A6: 1311511-3 | B6: 3 Downside: ARV 640k, Gut, vacant | C6: 19125 | D6: 27200 | E6: 329601 | F6: 1st | G6: 1728 | H6: 1113 | I6: 1925 | J6: 1 | K6: 409100 | L6: 350000 | M6: 640000 | N6: 3000 | O6: Gut | P6: 0 | Q6: Vacant | R6: 2500 | X6: 12 W Palmer deep dive scenario
A7: 1311511-4 | B7: 4 Upside: ARV 710k, Heavy, vacant | C7: 19125 | D7: 27200 | E7: 329601 | F7: 1st | G7: 1728 | H7: 1113 | I7: 1925 | J7: 1 | K7: 409100 | L7: 400000 | M7: 710000 | N7: 3400 | O7: Heavy | P7: 0 | Q7: Vacant | R7: 2500 | X7: 12 W Palmer deep dive scenario
A8: 1311511-5 | B8: 5 Junior plaintiff: base + $300k senior survives | C8: 19125 | D8: 27200 | E8: 329601 | F8: 2nd | G8: 1728 | H8: 1113 | I8: 1925 | J8: 1 | K8: 409100 | L8: 380000 | M8: 675000 | N8: 3200 | O8: Heavy | P8: 0 | Q8: Vacant | R8: 302500 | X8: 12 W Palmer deep dive scenario

Sheet Underwriting
A1: Property | C1: Result | K1: Timeline | O1: Costs | R1: Flip | Z1: Hold | AK1: Wholesale | AL1: Teardown
A2: Auction ID | B2: Address | C2: Best exit | D2: Max bid that hits target | E2: Check vs opening bid | F2: All-in cash at max bid | G2: Profit / return at max bid | H2: Buy box | I2: Other exits | J2: Flags | K2: Occupied? (1 = yes) | L2: Rehab months | M2: Flip: sale to sold | N2: Hold: sale to rent start | O2: Rehab budget (blind) | P2: Carry / month | Q2: Fixed deal costs (fees, legal, possession, liens) | R2: Flip: selling costs | S2: Flip: costs other than bid (pre-sale) | T2: Flip: profit before bid | U2: Flip: most the bid may cost (incl. premium, unpaid claims) | V2: Flip: max bid | W2: Flip: peak cash at max bid | X2: Flip: profit at max bid | Y2: Flip: annualized return at max bid | Z2: Hold: stabilized NOI / yr | AA2: Hold: costs other than bid | AB2: Hold: refi loan | AC2: Hold: cash flow after debt / yr | AD2: Hold: max bid at target yield on cost | AE2: Hold: max bid at target cash-on-cash | AF2: Hold: max bid (selected measure) | AG2: Hold: all-in cost at max bid | AH2: Hold: yield on cost at max bid | AI2: Hold: cash left in after refi | AJ2: Hold: cash-on-cash after refi | AK2: Wholesale: max bid (assign to a flipper, keep the fee) | AL2: Teardown: sale revenue | AM2: Teardown: costs other than bid | AN2: Teardown: max bid
A3: =IF(Deals!A3="","",Deals!A3) -> 1311511-0 | B3: =IF(A3="","",Deals!B3) -> 0 Prior screen (ARV 695k, Medium, occupied) | C3: =IF(A3="","",IF(MAX(V3,AF3)<=0,"Pass",IF(V3>=AF3,"Flip","Value-add hold"))) -> Flip | D3: =IF(A3="","",MAX(V3,AF3)) -> 327876.17 | E3: =IF(A3="","",IF(D3<=0,"Pass",IF(N(Deals!D3)<=1,"$1 = awaiting minimum bid; re-check the morning of Nov 3",IF(D3<Deals!D3,"Max bid below opening bid: pass","Room of "&TEXT(D3-Deals!D3,"$#,##0")&" over opening bid")))) -> Room of $300,676 over opening bid | F3: =IF(A3="","",IF(C3="Flip",W3,IF(C3="Value-add hold",AG3,0))) -> 489663.26 | G3: =IF(A3="","",IF(C3="Flip",TEXT(X3,"$#,##0")&" profit, "&TEXT(Y3,"0%")&"/yr over "&TEXT(M3,"0")&" mo",IF(C3="Value-add hold",TEXT(AH3,"0.0%")&" yield on cost; "&IF(ISNUMBER(AJ3),TEXT(AJ3,"0.0%")&" cash-on-cash after refi","all cash out at refi"),""))) -> $140,778 profit, 15%/yr over 23 mo | H3: =IF(A3="","",IF(C3="Flip",IF(W3<=FlipCeiling,"In $300k flip box","Over flip ceiling: needs to be exceptional"),IF(C3="Value-add hold","Value-add",""))) -> Over flip ceiling: needs to be exceptional | I3: =IF(A3="","",TRIM(IF(AK3>D3,"Wholesale assignment supports "&TEXT(AK3,"$#,##0")&". ","")&IF(AND(ISNUMBER(AN3),N(AN3)>D3),"Teardown/new units supports "&TEXT(AN3,"$#,##0")&".",""))) -> Wholesale assignment supports $349,086. | J3: =IF(A3="","",TRIM(IF(Deals!F3="2nd","Plaintiff is 2nd: add senior mortgage to surviving liens. ",IF(Deals!F3<>"1st","Lien position unconfirmed. ",""))&IF(N(Deals!M3)=0,"No ARV yet. ","")&IF(N(Deals!G3)=0,"No building sf: rehab is allowance only. ","")&IF(AND(N(Deals!S3)>0,D3>0,D3*(1-RTTPurchase)-SheriffCostsFromBid<N(Deals!S3)),"City claims not fully paid at max bid; unpaid part is counted as cost. ","")&IF(K3=1,"Occupancy assumed: +"&TEXT(EjectMonths,"0")&" mo and possession cost. ",""))) -> Occupancy assumed: +5 mo and possession cost. | K3: =IF(A3="","",IF(OR(Deals!Q3="Occupied",AND(Deals!Q3<>"Vacant",UnknownAsOccupied="Y")),1,0)) -> 1 | L3: =IF(A3="","",IFERROR(INDEX(ScopeMonths,MATCH(Deals!O3,ScopeNames,0)),INDEX(ScopeMonths,3))) -> 3 | M3: =IF(A3="","",DeedMonths+K3*EjectMonths+L3+SellMonths) -> 23 | N3: =IF(A3="","",DeedMonths+K3*EjectMonths+L3+LeaseUpMonths) -> 22 | O3: =IF(A3="","",N(Deals!G3)*IFERROR(INDEX(ScopePSF,MATCH(Deals!O3,ScopeNames,0)),INDEX(ScopePSF,3))*(1+Contingency)+BlindAllowance+N(Deals!P3)) -> 124048 | P3: =IF(A3="","",IF(N(Deals!K3)>0,Deals!K3,N(Deals!M3))*TaxRate/12+VacantInsMo+SecuringMo+UtilitiesMo+N(Deals!T3)) -> 902.21515 | Q3: =IF(A3="","",SheriffFees+PurchaseTitle+CompelDeedLegal+K3*PossessionCost+N(Deals!R3)+N(Deals!T3)*HOAArrearsMonths) -> 12070 | R3: =IF(A3="","",N(Deals!M3)*(BrokerPct+SellerRTT+SellClosingPct+ConcessionsPct)) -> 64558.55 | S3: =IF(A3="","",Q3+O3+P3*M3) -> 156868.95 | T3: =IF(A3="","",N(Deals!M3)-R3-S3) -> 473572.5 | U3: =IF(A3="","",MIN(T3-FlipTarget,(T3-FlipMinAnnROI*M3/12*S3)/(1+FlipMinAnnROI*M3/12))) -> 332794.31 | V3: =IF(A3="","",IF(N(Deals!S3)=0,MAX(0,(U3)/(1+BuyerPremium)),IF((U3)>=(N(Deals!S3)+SheriffCostsFromBid)/(1-RTTPurchase)*(1+BuyerPremium),(U3)/(1+BuyerPremium),MAX(0,((U3)-N(Deals!S3)-SheriffCostsFromBid)/(BuyerPremium+RTTPurchase))))) -> 327876.17 | W3: =IF(A3="","",((V3)*(1+BuyerPremium)+IF(N(Deals!S3)=0,0,MIN(N(Deals!S3),MAX(0,N(Deals!S3)+SheriffCostsFromBid-(V3)*(1-RTTPurchase)))))+S3) -> 489663.26 | X3: =IF(A3="","",T3-((V3)*(1+BuyerPremium)+IF(N(Deals!S3)=0,0,MIN(N(Deals!S3),MAX(0,N(Deals!S3)+SheriffCostsFromBid-(V3)*(1-RTTPurchase)))))) -> 140778.19 | Y3: =IF(A3="","",IFERROR(X3/W3/(M3/12),0)) -> 0.15 | Z3: =IF(A3="","",N(Deals!N3)*12*(1-Vacancy)*(1-MgmtPct-MaintPct-CapexPct)-N(Deals!M3)*TaxRate-MAX(1,N(Deals!J3))*(InsPerUnit+WaterPerUnit)-N(Deals!T3)*12) -> 12923.39 | AA3: =IF(A3="","",Q3+O3+P3*N3) -> 155966.73 | AB3: =IF(A3="","",MAX(0,MIN(RefiLTV*N(Deals!M3),Z3/(RefiDSCR*12*PMT(RefiRate/12,RefiTerm*12,-1))))) -> 131558.02 | AC3: =IF(A3="","",Z3-AB3*12*PMT(RefiRate/12,RefiTerm*12,-1)) -> 2153.8983 | AD3: =IF(A3="","",IF(N(Deals!S3)=0,MAX(0,(Z3/HoldTarget-AA3)/(1+BuyerPremium)),IF((Z3/HoldTarget-AA3)>=(N(Deals!S3)+SheriffCostsFromBid)/(1-RTTPurchase)*(1+BuyerPremium),(Z3/HoldTarget-AA3)/(1+BuyerPremium),MAX(0,((Z3/HoldTarget-AA3)-N(Deals!S3)-SheriffCostsFromBid)/(BuyerPremium+RTTPurchase))))) -> 0 | AE3: =IF(A3="","",IF(AC3<=0,0,IF(N(Deals!S3)=0,MAX(0,(AC3/HoldTarget+AB3*(1-RefiCostPct)-AA3)/(1+BuyerPremium)),IF((AC3/HoldTarget+AB3*(1-RefiCostPct)-AA3)>=(N(Deals!S3)+SheriffCostsFromBid)/(1-RTTPurchase)*(1+BuyerPremium),(AC3/HoldTarget+AB3*(1-RefiCostPct)-AA3)/(1+BuyerPremium),MAX(0,((AC3/HoldTarget+AB3*(1-RefiCostPct)-AA3)-N(Deals!S3)-SheriffCostsFromBid)/(BuyerPremium+RTTPurchase)))))) -> 0 | AF3: =IF(A3="","",IF(HoldMeasure="Cash-on-cash",AE3,AD3)) -> 0 | AG3: =IF(A3="","",((AF3)*(1+BuyerPremium)+IF(N(Deals!S3)=0,0,MIN(N(Deals!S3),MAX(0,N(Deals!S3)+SheriffCostsFromBid-(AF3)*(1-RTTPurchase)))))+AA3) -> 155966.73 | AH3: =IF(A3="","",IFERROR(Z3/AG3,0)) -> 0.082859913 | AI3: =IF(A3="","",AG3-AB3*(1-RefiCostPct)) -> 28355.449 | AJ3: =IF(A3="","",IF(AI3<=0,"All cash out",AC3/AI3)) -> 0.075960649 | AK3: =IF(A3="","",IF(N(Deals!S3)=0,MAX(0,(T3-BuyerMarginPct*N(Deals!M3)-WholesaleMinFee)/(1+BuyerPremium)),IF((T3-BuyerMarginPct*N(Deals!M3)-WholesaleMinFee)>=(N(Deals!S3)+SheriffCostsFromBid)/(1-RTTPurchase)*(1+BuyerPremium),(T3-BuyerMarginPct*N(Deals!M3)-WholesaleMinFee)/(1+BuyerPremium),MAX(0,((T3-BuyerMarginPct*N(Deals!M3)-WholesaleMinFee)-N(Deals!S3)-SheriffCostsFromBid)/(BuyerPremium+RTTPurchase))))) -> 349086.21 | AL3: =IF(OR(A3="",N(Deals!U3)=0),"",Deals!U3*N(Deals!W3)) | AM3: =IF(AL3="","",DemoCost+N(Deals!V3)*BuildCostPSF*(1+SoftCostPct)+P3*(DeedMonths+K3*EjectMonths+BuildMonths+SellMonths)+Q3+AL3*(BrokerPct+SellerRTT+SellClosingPct+ConcessionsPct)) | AN3: =IF(AL3="","",IF(N(Deals!S3)=0,MAX(0,(AL3-AM3-MAX(FlipTarget,DevMarginPct*AL3))/(1+BuyerPremium)),IF((AL3-AM3-MAX(FlipTarget,DevMarginPct*AL3))>=(N(Deals!S3)+SheriffCostsFromBid)/(1-RTTPurchase)*(1+BuyerPremium),(AL3-AM3-MAX(FlipTarget,DevMarginPct*AL3))/(1+BuyerPremium),MAX(0,((AL3-AM3-MAX(FlipTarget,DevMarginPct*AL3))-N(Deals!S3)-SheriffCostsFromBid)/(BuyerPremium+RTTPurchase)))))
A4: =IF(Deals!A4="","",Deals!A4) -> 1311511-1 | B4: =IF(A4="","",Deals!B4) -> 1 Base: ARV 675k, Heavy (stalled 2019 demo), vacant | C4: =IF(A4="","",IF(MAX(V4,AF4)<=0,"Pass",IF(V4>=AF4,"Flip","Value-add hold"))) -> Flip | D4: =IF(A4="","",MAX(V4,AF4)) -> 274353.79 | E4: =IF(A4="","",IF(D4<=0,"Pass",IF(N(Deals!D4)<=1,"$1 = awaiting minimum bid; re-check the morning of Nov 3",IF(D4<Deals!D4,"Max bid below opening bid: pass","Room of "&TEXT(D4-Deals!D4,"$#,##0")&" over opening bid")))) -> Room of $247,154 over opening bid | F4: =IF(A4="","",IF(C4="Flip",W4,IF(C4="Value-add hold",AG4,0))) -> 489839.4 | G4: =IF(A4="","",IF(C4="Flip",TEXT(X4,"$#,##0")&" profit, "&TEXT(Y4,"0%")&"/yr over "&TEXT(M4,"0")&" mo",IF(C4="Value-add hold",TEXT(AH4,"0.0%")&" yield on cost; "&IF(ISNUMBER(AJ4),TEXT(AJ4,"0.0%")&" cash-on-cash after refi","all cash out at refi"),""))) -> $122,460 profit, 15%/yr over 20 mo | H4: =IF(A4="","",IF(C4="Flip",IF(W4<=FlipCeiling,"In $300k flip box","Over flip ceiling: needs to be exceptional"),IF(C4="Value-add hold","Value-add",""))) -> Over flip ceiling: needs to be exceptional | I4: =IF(A4="","",TRIM(IF(AK4>D4,"Wholesale assignment supports "&TEXT(AK4,"$#,##0")&". ","")&IF(AND(ISNUMBER(AN4),N(AN4)>D4),"Teardown/new units supports "&TEXT(AN4,"$#,##0")&".",""))) -> Wholesale assignment supports $280,472. | J4: =IF(A4="","",TRIM(IF(Deals!F4="2nd","Plaintiff is 2nd: add senior mortgage to surviving liens. ",IF(Deals!F4<>"1st","Lien position unconfirmed. ",""))&IF(N(Deals!M4)=0,"No ARV yet. ","")&IF(N(Deals!G4)=0,"No building sf: rehab is allowance only. ","")&IF(AND(N(Deals!S4)>0,D4>0,D4*(1-RTTPurchase)-SheriffCostsFromBid<N(Deals!S4)),"City claims not fully paid at max bid; unpaid part is counted as cost. ","")&IF(K4=1,"Occupancy assumed: +"&TEXT(EjectMonths,"0")&" mo and possession cost. ",""))) | K4: =IF(A4="","",IF(OR(Deals!Q4="Occupied",AND(Deals!Q4<>"Vacant",UnknownAsOccupied="Y")),1,0)) -> 0 | L4: =IF(A4="","",IFERROR(INDEX(ScopeMonths,MATCH(Deals!O4,ScopeNames,0)),INDEX(ScopeMonths,3))) -> 5 | M4: =IF(A4="","",DeedMonths+K4*EjectMonths+L4+SellMonths) -> 20 | N4: =IF(A4="","",DeedMonths+K4*EjectMonths+L4+LeaseUpMonths) -> 19 | O4: =IF(A4="","",N(Deals!G4)*IFERROR(INDEX(ScopePSF,MATCH(Deals!O4,ScopeNames,0)),INDEX(ScopePSF,3))*(1+Contingency)+BlindAllowance+N(Deals!P4)) -> 186256 | P4: =IF(A4="","",IF(N(Deals!K4)>0,Deals!K4,N(Deals!M4))*TaxRate/12+VacantInsMo+SecuringMo+UtilitiesMo+N(Deals!T4)) -> 902.21515 | Q4: =IF(A4="","",SheriffFees+PurchaseTitle+CompelDeedLegal+K4*PossessionCost+N(Deals!R4)+N(Deals!T4)*HOAArrearsMonths) -> 7070 | R4: =IF(A4="","",N(Deals!M4)*(BrokerPct+SellerRTT+SellClosingPct+ConcessionsPct)) -> 62700.75 | S4: =IF(A4="","",Q4+O4+P4*M4) -> 211370.3 | T4: =IF(A4="","",N(Deals!M4)-R4-S4) -> 400928.95 | U4: =IF(A4="","",MIN(T4-FlipTarget,(T4-FlipMinAnnROI*M4/12*S4)/(1+FlipMinAnnROI*M4/12))) -> 278469.1 | V4: =IF(A4="","",IF(N(Deals!S4)=0,MAX(0,(U4)/(1+BuyerPremium)),IF((U4)>=(N(Deals!S4)+SheriffCostsFromBid)/(1-RTTPurchase)*(1+BuyerPremium),(U4)/(1+BuyerPremium),MAX(0,((U4)-N(Deals!S4)-SheriffCostsFromBid)/(BuyerPremium+RTTPurchase))))) -> 274353.79 | W4: =IF(A4="","",((V4)*(1+BuyerPremium)+IF(N(Deals!S4)=0,0,MIN(N(Deals!S4),MAX(0,N(Deals!S4)+SheriffCostsFromBid-(V4)*(1-RTTPurchase)))))+S4) -> 489839.4 | X4: =IF(A4="","",T4-((V4)*(1+BuyerPremium)+IF(N(Deals!S4)=0,0,MIN(N(Deals!S4),MAX(0,N(Deals!S4)+SheriffCostsFromBid-(V4)*(1-RTTPurchase)))))) -> 122459.85 | Y4: =IF(A4="","",IFERROR(X4/W4/(M4/12),0)) -> 0.15 | Z4: =IF(A4="","",N(Deals!N4)*12*(1-Vacancy)*(1-MgmtPct-MaintPct-CapexPct)-N(Deals!M4)*TaxRate-MAX(1,N(Deals!J4))*(InsPerUnit+WaterPerUnit)-N(Deals!T4)*12) -> 17220.95 | AA4: =IF(A4="","",Q4+O4+P4*N4) -> 210468.09 | AB4: =IF(A4="","",MAX(0,MIN(RefiLTV*N(Deals!M4),Z4/(RefiDSCR*12*PMT(RefiRate/12,RefiTerm*12,-1))))) -> 175306.49 | AC4: =IF(A4="","",Z4-AB4*12*PMT(RefiRate/12,RefiTerm*12,-1)) -> 2870.1583 | AD4: =IF(A4="","",IF(N(Deals!S4)=0,MAX(0,(Z4/HoldTarget-AA4)/(1+BuyerPremium)),IF((Z4/HoldTarget-AA4)>=(N(Deals!S4)+SheriffCostsFromBid)/(1-RTTPurchase)*(1+BuyerPremium),(Z4/HoldTarget-AA4)/(1+BuyerPremium),MAX(0,((Z4/HoldTarget-AA4)-N(Deals!S4)-SheriffCostsFromBid)/(BuyerPremium+RTTPurchase))))) -> 0 | AE4: =IF(A4="","",IF(AC4<=0,0,IF(N(Deals!S4)=0,MAX(0,(AC4/HoldTarget+AB4*(1-RefiCostPct)-AA4)/(1+BuyerPremium)),IF((AC4/HoldTarget+AB4*(1-RefiCostPct)-AA4)>=(N(Deals!S4)+SheriffCostsFromBid)/(1-RTTPurchase)*(1+BuyerPremium),(AC4/HoldTarget+AB4*(1-RefiCostPct)-AA4)/(1+BuyerPremium),MAX(0,((AC4/HoldTarget+AB4*(1-RefiCostPct)-AA4)-N(Deals!S4)-SheriffCostsFromBid)/(BuyerPremium+RTTPurchase)))))) -> 0 | AF4: =IF(A4="","",IF(HoldMeasure="Cash-on-cash",AE4,AD4)) -> 0 | AG4: =IF(A4="","",((AF4)*(1+BuyerPremium)+IF(N(Deals!S4)=0,0,MIN(N(Deals!S4),MAX(0,N(Deals!S4)+SheriffCostsFromBid-(AF4)*(1-RTTPurchase)))))+AA4) -> 210468.09 | AH4: =IF(A4="","",IFERROR(Z4/AG4,0)) -> 0.081822143 | AI4: =IF(A4="","",AG4-AB4*(1-RefiCostPct)) -> 40420.791 | AJ4: =IF(A4="","",IF(AI4<=0,"All cash out",AC4/AI4)) -> 0.071006981 | AK4: =IF(A4="","",IF(N(Deals!S4)=0,MAX(0,(T4-BuyerMarginPct*N(Deals!M4)-WholesaleMinFee)/(1+BuyerPremium)),IF((T4-BuyerMarginPct*N(Deals!M4)-WholesaleMinFee)>=(N(Deals!S4)+SheriffCostsFromBid)/(1-RTTPurchase)*(1+BuyerPremium),(T4-BuyerMarginPct*N(Deals!M4)-WholesaleMinFee)/(1+BuyerPremium),MAX(0,((T4-BuyerMarginPct*N(Deals!M4)-WholesaleMinFee)-N(Deals!S4)-SheriffCostsFromBid)/(BuyerPremium+RTTPurchase))))) -> 280471.87 | AL4: =IF(OR(A4="",N(Deals!U4)=0),"",Deals!U4*N(Deals!W4)) | AM4: =IF(AL4="","",DemoCost+N(Deals!V4)*BuildCostPSF*(1+SoftCostPct)+P4*(DeedMonths+K4*EjectMonths+BuildMonths+SellMonths)+Q4+AL4*(BrokerPct+SellerRTT+SellClosingPct+ConcessionsPct)) | AN4: =IF(AL4="","",IF(N(Deals!S4)=0,MAX(0,(AL4-AM4-MAX(FlipTarget,DevMarginPct*AL4))/(1+BuyerPremium)),IF((AL4-AM4-MAX(FlipTarget,DevMarginPct*AL4))>=(N(Deals!S4)+SheriffCostsFromBid)/(1-RTTPurchase)*(1+BuyerPremium),(AL4-AM4-MAX(FlipTarget,DevMarginPct*AL4))/(1+BuyerPremium),MAX(0,((AL4-AM4-MAX(FlipTarget,DevMarginPct*AL4))-N(Deals!S4)-SheriffCostsFromBid)/(BuyerPremium+RTTPurchase)))))
A5: =IF(Deals!A5="","",Deals!A5) -> 1311511-2 | B5: =IF(A5="","",Deals!B5) -> 2 Base but occupied (squatter/holdover) | C5: =IF(A5="","",IF(MAX(V5,AF5)<=0,"Pass",IF(V5>=AF5,"Flip","Value-add hold"))) -> Flip | D5: =IF(A5="","",MAX(V5,AF5)) -> 242002.3 | E5: =IF(A5="","",IF(D5<=0,"Pass",IF(N(Deals!D5)<=1,"$1 = awaiting minimum bid; re-check the morning of Nov 3",IF(D5<Deals!D5,"Max bid below opening bid: pass","Room of "&TEXT(D5-Deals!D5,"$#,##0")&" over opening bid")))) -> Room of $214,802 over opening bid | F5: =IF(A5="","",IF(C5="Flip",W5,IF(C5="Value-add hold",AG5,0))) -> 466513.71 | G5: =IF(A5="","",IF(C5="Flip",TEXT(X5,"$#,##0")&" profit, "&TEXT(Y5,"0%")&"/yr over "&TEXT(M5,"0")&" mo",IF(C5="Value-add hold",TEXT(AH5,"0.0%")&" yield on cost; "&IF(ISNUMBER(AJ5),TEXT(AJ5,"0.0%")&" cash-on-cash after refi","all cash out at refi"),""))) -> $145,786 profit, 15%/yr over 25 mo | H5: =IF(A5="","",IF(C5="Flip",IF(W5<=FlipCeiling,"In $300k flip box","Over flip ceiling: needs to be exceptional"),IF(C5="Value-add hold","Value-add",""))) -> Over flip ceiling: needs to be exceptional | I5: =IF(A5="","",TRIM(IF(AK5>D5,"Wholesale assignment supports "&TEXT(AK5,"$#,##0")&". ","")&IF(AND(ISNUMBER(AN5),N(AN5)>D5),"Teardown/new units supports "&TEXT(AN5,"$#,##0")&".",""))) -> Wholesale assignment supports $271,101. | J5: =IF(A5="","",TRIM(IF(Deals!F5="2nd","Plaintiff is 2nd: add senior mortgage to surviving liens. ",IF(Deals!F5<>"1st","Lien position unconfirmed. ",""))&IF(N(Deals!M5)=0,"No ARV yet. ","")&IF(N(Deals!G5)=0,"No building sf: rehab is allowance only. ","")&IF(AND(N(Deals!S5)>0,D5>0,D5*(1-RTTPurchase)-SheriffCostsFromBid<N(Deals!S5)),"City claims not fully paid at max bid; unpaid part is counted as cost. ","")&IF(K5=1,"Occupancy assumed: +"&TEXT(EjectMonths,"0")&" mo and possession cost. ",""))) -> Occupancy assumed: +5 mo and possession cost. | K5: =IF(A5="","",IF(OR(Deals!Q5="Occupied",AND(Deals!Q5<>"Vacant",UnknownAsOccupied="Y")),1,0)) -> 1 | L5: =IF(A5="","",IFERROR(INDEX(ScopeMonths,MATCH(Deals!O5,ScopeNames,0)),INDEX(ScopeMonths,3))) -> 5 | M5: =IF(A5="","",DeedMonths+K5*EjectMonths+L5+SellMonths) -> 25 | N5: =IF(A5="","",DeedMonths+K5*EjectMonths+L5+LeaseUpMonths) -> 24 | O5: =IF(A5="","",N(Deals!G5)*IFERROR(INDEX(ScopePSF,MATCH(Deals!O5,ScopeNames,0)),INDEX(ScopePSF,3))*(1+Contingency)+BlindAllowance+N(Deals!P5)) -> 186256 | P5: =IF(A5="","",IF(N(Deals!K5)>0,Deals!K5,N(Deals!M5))*TaxRate/12+VacantInsMo+SecuringMo+UtilitiesMo+N(Deals!T5)) -> 902.21515 | Q5: =IF(A5="","",SheriffFees+PurchaseTitle+CompelDeedLegal+K5*PossessionCost+N(Deals!R5)+N(Deals!T5)*HOAArrearsMonths) -> 12070 | R5: =IF(A5="","",N(Deals!M5)*(BrokerPct+SellerRTT+SellClosingPct+ConcessionsPct)) -> 62700.75 | S5: =IF(A5="","",Q5+O5+P5*M5) -> 220881.38 | T5: =IF(A5="","",N(Deals!M5)-R5-S5) -> 391417.87 | U5: =IF(A5="","",MIN(T5-FlipTarget,(T5-FlipMinAnnROI*M5/12*S5)/(1+FlipMinAnnROI*M5/12))) -> 245632.34 | V5: =IF(A5="","",IF(N(Deals!S5)=0,MAX(0,(U5)/(1+BuyerPremium)),IF((U5)>=(N(Deals!S5)+SheriffCostsFromBid)/(1-RTTPurchase)*(1+BuyerPremium),(U5)/(1+BuyerPremium),MAX(0,((U5)-N(Deals!S5)-SheriffCostsFromBid)/(BuyerPremium+RTTPurchase))))) -> 242002.3 | W5: =IF(A5="","",((V5)*(1+BuyerPremium)+IF(N(Deals!S5)=0,0,MIN(N(Deals!S5),MAX(0,N(Deals!S5)+SheriffCostsFromBid-(V5)*(1-RTTPurchase)))))+S5) -> 466513.71 | X5: =IF(A5="","",T5-((V5)*(1+BuyerPremium)+IF(N(Deals!S5)=0,0,MIN(N(Deals!S5),MAX(0,N(Deals!S5)+SheriffCostsFromBid-(V5)*(1-RTTPurchase)))))) -> 145785.54 | Y5: =IF(A5="","",IFERROR(X5/W5/(M5/12),0)) -> 0.15 | Z5: =IF(A5="","",N(Deals!N5)*12*(1-Vacancy)*(1-MgmtPct-MaintPct-CapexPct)-N(Deals!M5)*TaxRate-MAX(1,N(Deals!J5))*(InsPerUnit+WaterPerUnit)-N(Deals!T5)*12) -> 17220.95 | AA5: =IF(A5="","",Q5+O5+P5*N5) -> 219979.16 | AB5: =IF(A5="","",MAX(0,MIN(RefiLTV*N(Deals!M5),Z5/(RefiDSCR*12*PMT(RefiRate/12,RefiTerm*12,-1))))) -> 175306.49 | AC5: =IF(A5="","",Z5-AB5*12*PMT(RefiRate/12,RefiTerm*12,-1)) -> 2870.1583 | AD5: =IF(A5="","",IF(N(Deals!S5)=0,MAX(0,(Z5/HoldTarget-AA5)/(1+BuyerPremium)),IF((Z5/HoldTarget-AA5)>=(N(Deals!S5)+SheriffCostsFromBid)/(1-RTTPurchase)*(1+BuyerPremium),(Z5/HoldTarget-AA5)/(1+BuyerPremium),MAX(0,((Z5/HoldTarget-AA5)-N(Deals!S5)-SheriffCostsFromBid)/(BuyerPremium+RTTPurchase))))) -> 0 | AE5: =IF(A5="","",IF(AC5<=0,0,IF(N(Deals!S5)=0,MAX(0,(AC5/HoldTarget+AB5*(1-RefiCostPct)-AA5)/(1+BuyerPremium)),IF((AC5/HoldTarget+AB5*(1-RefiCostPct)-AA5)>=(N(Deals!S5)+SheriffCostsFromBid)/(1-RTTPurchase)*(1+BuyerPremium),(AC5/HoldTarget+AB5*(1-RefiCostPct)-AA5)/(1+BuyerPremium),MAX(0,((AC5/HoldTarget+AB5*(1-RefiCostPct)-AA5)-N(Deals!S5)-SheriffCostsFromBid)/(BuyerPremium+RTTPurchase)))))) -> 0 | AF5: =IF(A5="","",IF(HoldMeasure="Cash-on-cash",AE5,AD5)) -> 0 | AG5: =IF(A5="","",((AF5)*(1+BuyerPremium)+IF(N(Deals!S5)=0,0,MIN(N(Deals!S5),MAX(0,N(Deals!S5)+SheriffCostsFromBid-(AF5)*(1-RTTPurchase)))))+AA5) -> 219979.16 | AH5: =IF(A5="","",IFERROR(Z5/AG5,0)) -> 0.07828446 | AI5: =IF(A5="","",AG5-AB5*(1-RefiCostPct)) -> 49931.866 | AJ5: =IF(A5="","",IF(AI5<=0,"All cash out",AC5/AI5)) -> 0.057481495 | AK5: =IF(A5="","",IF(N(Deals!S5)=0,MAX(0,(T5-BuyerMarginPct*N(Deals!M5)-WholesaleMinFee)/(1+BuyerPremium)),IF((T5-BuyerMarginPct*N(Deals!M5)-WholesaleMinFee)>=(N(Deals!S5)+SheriffCostsFromBid)/(1-RTTPurchase)*(1+BuyerPremium),(T5-BuyerMarginPct*N(Deals!M5)-WholesaleMinFee)/(1+BuyerPremium),MAX(0,((T5-BuyerMarginPct*N(Deals!M5)-WholesaleMinFee)-N(Deals!S5)-SheriffCostsFromBid)/(BuyerPremium+RTTPurchase))))) -> 271101.35 | AL5: =IF(OR(A5="",N(Deals!U5)=0),"",Deals!U5*N(Deals!W5)) | AM5: =IF(AL5="","",DemoCost+N(Deals!V5)*BuildCostPSF*(1+SoftCostPct)+P5*(DeedMonths+K5*EjectMonths+BuildMonths+SellMonths)+Q5+AL5*(BrokerPct+SellerRTT+SellClosingPct+ConcessionsPct)) | AN5: =IF(AL5="","",IF(N(Deals!S5)=0,MAX(0,(AL5-AM5-MAX(FlipTarget,DevMarginPct*AL5))/(1+BuyerPremium)),IF((AL5-AM5-MAX(FlipTarget,DevMarginPct*AL5))>=(N(Deals!S5)+SheriffCostsFromBid)/(1-RTTPurchase)*(1+BuyerPremium),(AL5-AM5-MAX(FlipTarget,DevMarginPct*AL5))/(1+BuyerPremium),MAX(0,((AL5-AM5-MAX(FlipTarget,DevMarginPct*AL5))-N(Deals!S5)-SheriffCostsFromBid)/(BuyerPremium+RTTPurchase)))))
A6: =IF(Deals!A6="","",Deals!A6) -> 1311511-3 | B6: =IF(A6="","",Deals!B6) -> 3 Downside: ARV 640k, Gut, vacant | C6: =IF(A6="","",IF(MAX(V6,AF6)<=0,"Pass",IF(V6>=AF6,"Flip","Value-add hold"))) -> Flip | D6: =IF(A6="","",MAX(V6,AF6)) -> 156861.98 | E6: =IF(A6="","",IF(D6<=0,"Pass",IF(N(Deals!D6)<=1,"$1 = awaiting minimum bid; re-check the morning of Nov 3",IF(D6<Deals!D6,"Max bid below opening bid: pass","Room of "&TEXT(D6-Deals!D6,"$#,##0")&" over opening bid")))) -> Room of $129,662 over opening bid | F6: =IF(A6="","",IF(C6="Flip",W6,IF(C6="Value-add hold",AG6,0))) -> 455333.65 | G6: =IF(A6="","",IF(C6="Flip",TEXT(X6,"$#,##0")&" profit, "&TEXT(Y6,"0%")&"/yr over "&TEXT(M6,"0")&" mo",IF(C6="Value-add hold",TEXT(AH6,"0.0%")&" yield on cost; "&IF(ISNUMBER(AJ6),TEXT(AJ6,"0.0%")&" cash-on-cash after refi","all cash out at refi"),""))) -> $125,217 profit, 15%/yr over 22 mo | H6: =IF(A6="","",IF(C6="Flip",IF(W6<=FlipCeiling,"In $300k flip box","Over flip ceiling: needs to be exceptional"),IF(C6="Value-add hold","Value-add",""))) -> Over flip ceiling: needs to be exceptional | I6: =IF(A6="","",TRIM(IF(AK6>D6,"Wholesale assignment supports "&TEXT(AK6,"$#,##0")&". ","")&IF(AND(ISNUMBER(AN6),N(AN6)>D6),"Teardown/new units supports "&TEXT(AN6,"$#,##0")&".",""))) -> Wholesale assignment supports $170,869. | J6: =IF(A6="","",TRIM(IF(Deals!F6="2nd","Plaintiff is 2nd: add senior mortgage to surviving liens. ",IF(Deals!F6<>"1st","Lien position unconfirmed. ",""))&IF(N(Deals!M6)=0,"No ARV yet. ","")&IF(N(Deals!G6)=0,"No building sf: rehab is allowance only. ","")&IF(AND(N(Deals!S6)>0,D6>0,D6*(1-RTTPurchase)-SheriffCostsFromBid<N(Deals!S6)),"City claims not fully paid at max bid; unpaid part is counted as cost. ","")&IF(K6=1,"Occupancy assumed: +"&TEXT(EjectMonths,"0")&" mo and possession cost. ",""))) | K6: =IF(A6="","",IF(OR(Deals!Q6="Occupied",AND(Deals!Q6<>"Vacant",UnknownAsOccupied="Y")),1,0)) -> 0 | L6: =IF(A6="","",IFERROR(INDEX(ScopeMonths,MATCH(Deals!O6,ScopeNames,0)),INDEX(ScopeMonths,3))) -> 7 | M6: =IF(A6="","",DeedMonths+K6*EjectMonths+L6+SellMonths) -> 22 | N6: =IF(A6="","",DeedMonths+K6*EjectMonths+L6+LeaseUpMonths) -> 21 | O6: =IF(A6="","",N(Deals!G6)*IFERROR(INDEX(ScopePSF,MATCH(Deals!O6,ScopeNames,0)),INDEX(ScopePSF,3))*(1+Contingency)+BlindAllowance+N(Deals!P6)) -> 269200 | P6: =IF(A6="","",IF(N(Deals!K6)>0,Deals!K6,N(Deals!M6))*TaxRate/12+VacantInsMo+SecuringMo+UtilitiesMo+N(Deals!T6)) -> 902.21515 | Q6: =IF(A6="","",SheriffFees+PurchaseTitle+CompelDeedLegal+K6*PossessionCost+N(Deals!R6)+N(Deals!T6)*HOAArrearsMonths) -> 7070 | R6: =IF(A6="","",N(Deals!M6)*(BrokerPct+SellerRTT+SellClosingPct+ConcessionsPct)) -> 59449.6 | S6: =IF(A6="","",Q6+O6+P6*M6) -> 296118.73 | T6: =IF(A6="","",N(Deals!M6)-R6-S6) -> 284431.67 | U6: =IF(A6="","",MIN(T6-FlipTarget,(T6-FlipMinAnnROI*M6/12*S6)/(1+FlipMinAnnROI*M6/12))) -> 159214.91 | V6: =IF(A6="","",IF(N(Deals!S6)=0,MAX(0,(U6)/(1+BuyerPremium)),IF((U6)>=(N(Deals!S6)+SheriffCostsFromBid)/(1-RTTPurchase)*(1+BuyerPremium),(U6)/(1+BuyerPremium),MAX(0,((U6)-N(Deals!S6)-SheriffCostsFromBid)/(BuyerPremium+RTTPurchase))))) -> 156861.98 | W6: =IF(A6="","",((V6)*(1+BuyerPremium)+IF(N(Deals!S6)=0,0,MIN(N(Deals!S6),MAX(0,N(Deals!S6)+SheriffCostsFromBid-(V6)*(1-RTTPurchase)))))+S6) -> 455333.65 | X6: =IF(A6="","",T6-((V6)*(1+BuyerPremium)+IF(N(Deals!S6)=0,0,MIN(N(Deals!S6),MAX(0,N(Deals!S6)+SheriffCostsFromBid-(V6)*(1-RTTPurchase)))))) -> 125216.75 | Y6: =IF(A6="","",IFERROR(X6/W6/(M6/12),0)) -> 0.15 | Z6: =IF(A6="","",N(Deals!N6)*12*(1-Vacancy)*(1-MgmtPct-MaintPct-CapexPct)-N(Deals!M6)*TaxRate-MAX(1,N(Deals!J6))*(InsPerUnit+WaterPerUnit)-N(Deals!T6)*12) -> 15925.28 | AA6: =IF(A6="","",Q6+O6+P6*N6) -> 295216.52 | AB6: =IF(A6="","",MAX(0,MIN(RefiLTV*N(Deals!M6),Z6/(RefiDSCR*12*PMT(RefiRate/12,RefiTerm*12,-1))))) -> 162116.78 | AC6: =IF(A6="","",Z6-AB6*12*PMT(RefiRate/12,RefiTerm*12,-1)) -> 2654.2133 | AD6: =IF(A6="","",IF(N(Deals!S6)=0,MAX(0,(Z6/HoldTarget-AA6)/(1+BuyerPremium)),IF((Z6/HoldTarget-AA6)>=(N(Deals!S6)+SheriffCostsFromBid)/(1-RTTPurchase)*(1+BuyerPremium),(Z6/HoldTarget-AA6)/(1+BuyerPremium),MAX(0,((Z6/HoldTarget-AA6)-N(Deals!S6)-SheriffCostsFromBid)/(BuyerPremium+RTTPurchase))))) -> 0 | AE6: =IF(A6="","",IF(AC6<=0,0,IF(N(Deals!S6)=0,MAX(0,(AC6/HoldTarget+AB6*(1-RefiCostPct)-AA6)/(1+BuyerPremium)),IF((AC6/HoldTarget+AB6*(1-RefiCostPct)-AA6)>=(N(Deals!S6)+SheriffCostsFromBid)/(1-RTTPurchase)*(1+BuyerPremium),(AC6/HoldTarget+AB6*(1-RefiCostPct)-AA6)/(1+BuyerPremium),MAX(0,((AC6/HoldTarget+AB6*(1-RefiCostPct)-AA6)-N(Deals!S6)-SheriffCostsFromBid)/(BuyerPremium+RTTPurchase)))))) -> 0 | AF6: =IF(A6="","",IF(HoldMeasure="Cash-on-cash",AE6,AD6)) -> 0 | AG6: =IF(A6="","",((AF6)*(1+BuyerPremium)+IF(N(Deals!S6)=0,0,MIN(N(Deals!S6),MAX(0,N(Deals!S6)+SheriffCostsFromBid-(AF6)*(1-RTTPurchase)))))+AA6) -> 295216.52 | AH6: =IF(A6="","",IFERROR(Z6/AG6,0)) -> 0.053944407 | AI6: =IF(A6="","",AG6-AB6*(1-RefiCostPct)) -> 137963.24 | AJ6: =IF(A6="","",IF(AI6<=0,"All cash out",AC6/AI6)) -> 0.019238555 | AK6: =IF(A6="","",IF(N(Deals!S6)=0,MAX(0,(T6-BuyerMarginPct*N(Deals!M6)-WholesaleMinFee)/(1+BuyerPremium)),IF((T6-BuyerMarginPct*N(Deals!M6)-WholesaleMinFee)>=(N(Deals!S6)+SheriffCostsFromBid)/(1-RTTPurchase)*(1+BuyerPremium),(T6-BuyerMarginPct*N(Deals!M6)-WholesaleMinFee)/(1+BuyerPremium),MAX(0,((T6-BuyerMarginPct*N(Deals!M6)-WholesaleMinFee)-N(Deals!S6)-SheriffCostsFromBid)/(BuyerPremium+RTTPurchase))))) -> 170868.64 | AL6: =IF(OR(A6="",N(Deals!U6)=0),"",Deals!U6*N(Deals!W6)) | AM6: =IF(AL6="","",DemoCost+N(Deals!V6)*BuildCostPSF*(1+SoftCostPct)+P6*(DeedMonths+K6*EjectMonths+BuildMonths+SellMonths)+Q6+AL6*(BrokerPct+SellerRTT+SellClosingPct+ConcessionsPct)) | AN6: =IF(AL6="","",IF(N(Deals!S6)=0,MAX(0,(AL6-AM6-MAX(FlipTarget,DevMarginPct*AL6))/(1+BuyerPremium)),IF((AL6-AM6-MAX(FlipTarget,DevMarginPct*AL6))>=(N(Deals!S6)+SheriffCostsFromBid)/(1-RTTPurchase)*(1+BuyerPremium),(AL6-AM6-MAX(FlipTarget,DevMarginPct*AL6))/(1+BuyerPremium),MAX(0,((AL6-AM6-MAX(FlipTarget,DevMarginPct*AL6))-N(Deals!S6)-SheriffCostsFromBid)/(BuyerPremium+RTTPurchase)))))
A7: =IF(Deals!A7="","",Deals!A7) -> 1311511-4 | B7: =IF(A7="","",Deals!B7) -> 4 Upside: ARV 710k, Heavy, vacant | C7: =IF(A7="","",IF(MAX(V7,AF7)<=0,"Pass",IF(V7>=AF7,"Flip","Value-add hold"))) -> Flip | D7: =IF(A7="","",MAX(V7,AF7)) -> 299377.51 | E7: =IF(A7="","",IF(D7<=0,"Pass",IF(N(Deals!D7)<=1,"$1 = awaiting minimum bid; re-check the morning of Nov 3",IF(D7<Deals!D7,"Max bid below opening bid: pass","Room of "&TEXT(D7-Deals!D7,"$#,##0")&" over opening bid")))) -> Room of $272,178 over opening bid | F7: =IF(A7="","",IF(C7="Flip",W7,IF(C7="Value-add hold",AG7,0))) -> 515238.48 | G7: =IF(A7="","",IF(C7="Flip",TEXT(X7,"$#,##0")&" profit, "&TEXT(Y7,"0%")&"/yr over "&TEXT(M7,"0")&" mo",IF(C7="Value-add hold",TEXT(AH7,"0.0%")&" yield on cost; "&IF(ISNUMBER(AJ7),TEXT(AJ7,"0.0%")&" cash-on-cash after refi","all cash out at refi"),""))) -> $128,810 profit, 15%/yr over 20 mo | H7: =IF(A7="","",IF(C7="Flip",IF(W7<=FlipCeiling,"In $300k flip box","Over flip ceiling: needs to be exceptional"),IF(C7="Value-add hold","Value-add",""))) -> Over flip ceiling: needs to be exceptional | I7: =IF(A7="","",TRIM(IF(AK7>D7,"Wholesale assignment supports "&TEXT(AK7,"$#,##0")&". ","")&IF(AND(ISNUMBER(AN7),N(AN7)>D7),"Teardown/new units supports "&TEXT(AN7,"$#,##0")&".",""))) -> Wholesale assignment supports $306,579. | J7: =IF(A7="","",TRIM(IF(Deals!F7="2nd","Plaintiff is 2nd: add senior mortgage to surviving liens. ",IF(Deals!F7<>"1st","Lien position unconfirmed. ",""))&IF(N(Deals!M7)=0,"No ARV yet. ","")&IF(N(Deals!G7)=0,"No building sf: rehab is allowance only. ","")&IF(AND(N(Deals!S7)>0,D7>0,D7*(1-RTTPurchase)-SheriffCostsFromBid<N(Deals!S7)),"City claims not fully paid at max bid; unpaid part is counted as cost. ","")&IF(K7=1,"Occupancy assumed: +"&TEXT(EjectMonths,"0")&" mo and possession cost. ",""))) | K7: =IF(A7="","",IF(OR(Deals!Q7="Occupied",AND(Deals!Q7<>"Vacant",UnknownAsOccupied="Y")),1,0)) -> 0 | L7: =IF(A7="","",IFERROR(INDEX(ScopeMonths,MATCH(Deals!O7,ScopeNames,0)),INDEX(ScopeMonths,3))) -> 5 | M7: =IF(A7="","",DeedMonths+K7*EjectMonths+L7+SellMonths) -> 20 | N7: =IF(A7="","",DeedMonths+K7*EjectMonths+L7+LeaseUpMonths) -> 19 | O7: =IF(A7="","",N(Deals!G7)*IFERROR(INDEX(ScopePSF,MATCH(Deals!O7,ScopeNames,0)),INDEX(ScopePSF,3))*(1+Contingency)+BlindAllowance+N(Deals!P7)) -> 186256 | P7: =IF(A7="","",IF(N(Deals!K7)>0,Deals!K7,N(Deals!M7))*TaxRate/12+VacantInsMo+SecuringMo+UtilitiesMo+N(Deals!T7)) -> 902.21515 | Q7: =IF(A7="","",SheriffFees+PurchaseTitle+CompelDeedLegal+K7*PossessionCost+N(Deals!R7)+N(Deals!T7)*HOAArrearsMonths) -> 7070 | R7: =IF(A7="","",N(Deals!M7)*(BrokerPct+SellerRTT+SellClosingPct+ConcessionsPct)) -> 65951.9 | S7: =IF(A7="","",Q7+O7+P7*M7) -> 211370.3 | T7: =IF(A7="","",N(Deals!M7)-R7-S7) -> 432677.8 | U7: =IF(A7="","",MIN(T7-FlipTarget,(T7-FlipMinAnnROI*M7/12*S7)/(1+FlipMinAnnROI*M7/12))) -> 303868.18 | V7: =IF(A7="","",IF(N(Deals!S7)=0,MAX(0,(U7)/(1+BuyerPremium)),IF((U7)>=(N(Deals!S7)+SheriffCostsFromBid)/(1-RTTPurchase)*(1+BuyerPremium),(U7)/(1+BuyerPremium),MAX(0,((U7)-N(Deals!S7)-SheriffCostsFromBid)/(BuyerPremium+RTTPurchase))))) -> 299377.51 | W7: =IF(A7="","",((V7)*(1+BuyerPremium)+IF(N(Deals!S7)=0,0,MIN(N(Deals!S7),MAX(0,N(Deals!S7)+SheriffCostsFromBid-(V7)*(1-RTTPurchase)))))+S7) -> 515238.48 | X7: =IF(A7="","",T7-((V7)*(1+BuyerPremium)+IF(N(Deals!S7)=0,0,MIN(N(Deals!S7),MAX(0,N(Deals!S7)+SheriffCostsFromBid-(V7)*(1-RTTPurchase)))))) -> 128809.62 | Y7: =IF(A7="","",IFERROR(X7/W7/(M7/12),0)) -> 0.15 | Z7: =IF(A7="","",N(Deals!N7)*12*(1-Vacancy)*(1-MgmtPct-MaintPct-CapexPct)-N(Deals!M7)*TaxRate-MAX(1,N(Deals!J7))*(InsPerUnit+WaterPerUnit)-N(Deals!T7)*12) -> 18516.62 | AA7: =IF(A7="","",Q7+O7+P7*N7) -> 210468.09 | AB7: =IF(A7="","",MAX(0,MIN(RefiLTV*N(Deals!M7),Z7/(RefiDSCR*12*PMT(RefiRate/12,RefiTerm*12,-1))))) -> 188496.2 | AC7: =IF(A7="","",Z7-AB7*12*PMT(RefiRate/12,RefiTerm*12,-1)) -> 3086.1033 | AD7: =IF(A7="","",IF(N(Deals!S7)=0,MAX(0,(Z7/HoldTarget-AA7)/(1+BuyerPremium)),IF((Z7/HoldTarget-AA7)>=(N(Deals!S7)+SheriffCostsFromBid)/(1-RTTPurchase)*(1+BuyerPremium),(Z7/HoldTarget-AA7)/(1+BuyerPremium),MAX(0,((Z7/HoldTarget-AA7)-N(Deals!S7)-SheriffCostsFromBid)/(BuyerPremium+RTTPurchase))))) -> 0 | AE7: =IF(A7="","",IF(AC7<=0,0,IF(N(Deals!S7)=0,MAX(0,(AC7/HoldTarget+AB7*(1-RefiCostPct)-AA7)/(1+BuyerPremium)),IF((AC7/HoldTarget+AB7*(1-RefiCostPct)-AA7)>=(N(Deals!S7)+SheriffCostsFromBid)/(1-RTTPurchase)*(1+BuyerPremium),(AC7/HoldTarget+AB7*(1-RefiCostPct)-AA7)/(1+BuyerPremium),MAX(0,((AC7/HoldTarget+AB7*(1-RefiCostPct)-AA7)-N(Deals!S7)-SheriffCostsFromBid)/(BuyerPremium+RTTPurchase)))))) -> 0 | AF7: =IF(A7="","",IF(HoldMeasure="Cash-on-cash",AE7,AD7)) -> 0 | AG7: =IF(A7="","",((AF7)*(1+BuyerPremium)+IF(N(Deals!S7)=0,0,MIN(N(Deals!S7),MAX(0,N(Deals!S7)+SheriffCostsFromBid-(AF7)*(1-RTTPurchase)))))+AA7) -> 210468.09 | AH7: =IF(A7="","",IFERROR(Z7/AG7,0)) -> 0.087978278 | AI7: =IF(A7="","",AG7-AB7*(1-RefiCostPct)) -> 27626.77 | AJ7: =IF(A7="","",IF(AI7<=0,"All cash out",AC7/AI7)) -> 0.11170699 | AK7: =IF(A7="","",IF(N(Deals!S7)=0,MAX(0,(T7-BuyerMarginPct*N(Deals!M7)-WholesaleMinFee)/(1+BuyerPremium)),IF((T7-BuyerMarginPct*N(Deals!M7)-WholesaleMinFee)>=(N(Deals!S7)+SheriffCostsFromBid)/(1-RTTPurchase)*(1+BuyerPremium),(T7-BuyerMarginPct*N(Deals!M7)-WholesaleMinFee)/(1+BuyerPremium),MAX(0,((T7-BuyerMarginPct*N(Deals!M7)-WholesaleMinFee)-N(Deals!S7)-SheriffCostsFromBid)/(BuyerPremium+RTTPurchase))))) -> 306579.11 | AL7: =IF(OR(A7="",N(Deals!U7)=0),"",Deals!U7*N(Deals!W7)) | AM7: =IF(AL7="","",DemoCost+N(Deals!V7)*BuildCostPSF*(1+SoftCostPct)+P7*(DeedMonths+K7*EjectMonths+BuildMonths+SellMonths)+Q7+AL7*(BrokerPct+SellerRTT+SellClosingPct+ConcessionsPct)) | AN7: =IF(AL7="","",IF(N(Deals!S7)=0,MAX(0,(AL7-AM7-MAX(FlipTarget,DevMarginPct*AL7))/(1+BuyerPremium)),IF((AL7-AM7-MAX(FlipTarget,DevMarginPct*AL7))>=(N(Deals!S7)+SheriffCostsFromBid)/(1-RTTPurchase)*(1+BuyerPremium),(AL7-AM7-MAX(FlipTarget,DevMarginPct*AL7))/(1+BuyerPremium),MAX(0,((AL7-AM7-MAX(FlipTarget,DevMarginPct*AL7))-N(Deals!S7)-SheriffCostsFromBid)/(BuyerPremium+RTTPurchase)))))
A8: =IF(Deals!A8="","",Deals!A8) -> 1311511-5 | B8: =IF(A8="","",Deals!B8) -> 5 Junior plaintiff: base + $300k senior survives | C8: =IF(A8="","",IF(MAX(V8,AF8)<=0,"Pass",IF(V8>=AF8,"Flip","Value-add hold"))) -> Pass | D8: =IF(A8="","",MAX(V8,AF8)) -> 0 | E8: =IF(A8="","",IF(D8<=0,"Pass",IF(N(Deals!D8)<=1,"$1 = awaiting minimum bid; re-check the morning of Nov 3",IF(D8<Deals!D8,"Max bid below opening bid: pass","Room of "&TEXT(D8-Deals!D8,"$#,##0")&" over opening bid")))) -> Pass | F8: =IF(A8="","",IF(C8="Flip",W8,IF(C8="Value-add hold",AG8,0))) -> 0 | G8: =IF(A8="","",IF(C8="Flip",TEXT(X8,"$#,##0")&" profit, "&TEXT(Y8,"0%")&"/yr over "&TEXT(M8,"0")&" mo",IF(C8="Value-add hold",TEXT(AH8,"0.0%")&" yield on cost; "&IF(ISNUMBER(AJ8),TEXT(AJ8,"0.0%")&" cash-on-cash after refi","all cash out at refi"),""))) | H8: =IF(A8="","",IF(C8="Flip",IF(W8<=FlipCeiling,"In $300k flip box","Over flip ceiling: needs to be exceptional"),IF(C8="Value-add hold","Value-add",""))) | I8: =IF(A8="","",TRIM(IF(AK8>D8,"Wholesale assignment supports "&TEXT(AK8,"$#,##0")&". ","")&IF(AND(ISNUMBER(AN8),N(AN8)>D8),"Teardown/new units supports "&TEXT(AN8,"$#,##0")&".",""))) | J8: =IF(A8="","",TRIM(IF(Deals!F8="2nd","Plaintiff is 2nd: add senior mortgage to surviving liens. ",IF(Deals!F8<>"1st","Lien position unconfirmed. ",""))&IF(N(Deals!M8)=0,"No ARV yet. ","")&IF(N(Deals!G8)=0,"No building sf: rehab is allowance only. ","")&IF(AND(N(Deals!S8)>0,D8>0,D8*(1-RTTPurchase)-SheriffCostsFromBid<N(Deals!S8)),"City claims not fully paid at max bid; unpaid part is counted as cost. ","")&IF(K8=1,"Occupancy assumed: +"&TEXT(EjectMonths,"0")&" mo and possession cost. ",""))) -> Plaintiff is 2nd: add senior mortgage to surviving liens. | K8: =IF(A8="","",IF(OR(Deals!Q8="Occupied",AND(Deals!Q8<>"Vacant",UnknownAsOccupied="Y")),1,0)) -> 0 | L8: =IF(A8="","",IFERROR(INDEX(ScopeMonths,MATCH(Deals!O8,ScopeNames,0)),INDEX(ScopeMonths,3))) -> 5 | M8: =IF(A8="","",DeedMonths+K8*EjectMonths+L8+SellMonths) -> 20 | N8: =IF(A8="","",DeedMonths+K8*EjectMonths+L8+LeaseUpMonths) -> 19 | O8: =IF(A8="","",N(Deals!G8)*IFERROR(INDEX(ScopePSF,MATCH(Deals!O8,ScopeNames,0)),INDEX(ScopePSF,3))*(1+Contingency)+BlindAllowance+N(Deals!P8)) -> 186256 | P8: =IF(A8="","",IF(N(Deals!K8)>0,Deals!K8,N(Deals!M8))*TaxRate/12+VacantInsMo+SecuringMo+UtilitiesMo+N(Deals!T8)) -> 902.21515 | Q8: =IF(A8="","",SheriffFees+PurchaseTitle+CompelDeedLegal+K8*PossessionCost+N(Deals!R8)+N(Deals!T8)*HOAArrearsMonths) -> 307070 | R8: =IF(A8="","",N(Deals!M8)*(BrokerPct+SellerRTT+SellClosingPct+ConcessionsPct)) -> 62700.75 | S8: =IF(A8="","",Q8+O8+P8*M8) -> 511370.3 | T8: =IF(A8="","",N(Deals!M8)-R8-S8) -> 100928.95 | U8: =IF(A8="","",MIN(T8-FlipTarget,(T8-FlipMinAnnROI*M8/12*S8)/(1+FlipMinAnnROI*M8/12))) -> -21530.903 | V8: =IF(A8="","",IF(N(Deals!S8)=0,MAX(0,(U8)/(1+BuyerPremium)),IF((U8)>=(N(Deals!S8)+SheriffCostsFromBid)/(1-RTTPurchase)*(1+BuyerPremium),(U8)/(1+BuyerPremium),MAX(0,((U8)-N(Deals!S8)-SheriffCostsFromBid)/(BuyerPremium+RTTPurchase))))) -> 0 | W8: =IF(A8="","",((V8)*(1+BuyerPremium)+IF(N(Deals!S8)=0,0,MIN(N(Deals!S8),MAX(0,N(Deals!S8)+SheriffCostsFromBid-(V8)*(1-RTTPurchase)))))+S8) -> 511370.3 | X8: =IF(A8="","",T8-((V8)*(1+BuyerPremium)+IF(N(Deals!S8)=0,0,MIN(N(Deals!S8),MAX(0,N(Deals!S8)+SheriffCostsFromBid-(V8)*(1-RTTPurchase)))))) -> 100928.95 | Y8: =IF(A8="","",IFERROR(X8/W8/(M8/12),0)) -> 0.11842175 | Z8: =IF(A8="","",N(Deals!N8)*12*(1-Vacancy)*(1-MgmtPct-MaintPct-CapexPct)-N(Deals!M8)*TaxRate-MAX(1,N(Deals!J8))*(InsPerUnit+WaterPerUnit)-N(Deals!T8)*12) -> 17220.95 | AA8: =IF(A8="","",Q8+O8+P8*N8) -> 510468.09 | AB8: =IF(A8="","",MAX(0,MIN(RefiLTV*N(Deals!M8),Z8/(RefiDSCR*12*PMT(RefiRate/12,RefiTerm*12,-1))))) -> 175306.49 | AC8: =IF(A8="","",Z8-AB8*12*PMT(RefiRate/12,RefiTerm*12,-1)) -> 2870.1583 | AD8: =IF(A8="","",IF(N(Deals!S8)=0,MAX(0,(Z8/HoldTarget-AA8)/(1+BuyerPremium)),IF((Z8/HoldTarget-AA8)>=(N(Deals!S8)+SheriffCostsFromBid)/(1-RTTPurchase)*(1+BuyerPremium),(Z8/HoldTarget-AA8)/(1+BuyerPremium),MAX(0,((Z8/HoldTarget-AA8)-N(Deals!S8)-SheriffCostsFromBid)/(BuyerPremium+RTTPurchase))))) -> 0 | AE8: =IF(A8="","",IF(AC8<=0,0,IF(N(Deals!S8)=0,MAX(0,(AC8/HoldTarget+AB8*(1-RefiCostPct)-AA8)/(1+BuyerPremium)),IF((AC8/HoldTarget+AB8*(1-RefiCostPct)-AA8)>=(N(Deals!S8)+SheriffCostsFromBid)/(1-RTTPurchase)*(1+BuyerPremium),(AC8/HoldTarget+AB8*(1-RefiCostPct)-AA8)/(1+BuyerPremium),MAX(0,((AC8/HoldTarget+AB8*(1-RefiCostPct)-AA8)-N(Deals!S8)-SheriffCostsFromBid)/(BuyerPremium+RTTPurchase)))))) -> 0 | AF8: =IF(A8="","",IF(HoldMeasure="Cash-on-cash",AE8,AD8)) -> 0 | AG8: =IF(A8="","",((AF8)*(1+BuyerPremium)+IF(N(Deals!S8)=0,0,MIN(N(Deals!S8),MAX(0,N(Deals!S8)+SheriffCostsFromBid-(AF8)*(1-RTTPurchase)))))+AA8) -> 510468.09 | AH8: =IF(A8="","",IFERROR(Z8/AG8,0)) -> 0.033735605 | AI8: =IF(A8="","",AG8-AB8*(1-RefiCostPct)) -> 340420.79 | AJ8: =IF(A8="","",IF(AI8<=0,"All cash out",AC8/AI8)) -> 0.0084312075 | AK8: =IF(A8="","",IF(N(Deals!S8)=0,MAX(0,(T8-BuyerMarginPct*N(Deals!M8)-WholesaleMinFee)/(1+BuyerPremium)),IF((T8-BuyerMarginPct*N(Deals!M8)-WholesaleMinFee)>=(N(Deals!S8)+SheriffCostsFromBid)/(1-RTTPurchase)*(1+BuyerPremium),(T8-BuyerMarginPct*N(Deals!M8)-WholesaleMinFee)/(1+BuyerPremium),MAX(0,((T8-BuyerMarginPct*N(Deals!M8)-WholesaleMinFee)-N(Deals!S8)-SheriffCostsFromBid)/(BuyerPremium+RTTPurchase))))) -> 0 | AL8: =IF(OR(A8="",N(Deals!U8)=0),"",Deals!U8*N(Deals!W8)) | AM8: =IF(AL8="","",DemoCost+N(Deals!V8)*BuildCostPSF*(1+SoftCostPct)+P8*(DeedMonths+K8*EjectMonths+BuildMonths+SellMonths)+Q8+AL8*(BrokerPct+SellerRTT+SellClosingPct+ConcessionsPct)) | AN8: =IF(AL8="","",IF(N(Deals!S8)=0,MAX(0,(AL8-AM8-MAX(FlipTarget,DevMarginPct*AL8))/(1+BuyerPremium)),IF((AL8-AM8-MAX(FlipTarget,DevMarginPct*AL8))>=(N(Deals!S8)+SheriffCostsFromBid)/(1-RTTPurchase)*(1+BuyerPremium),(AL8-AM8-MAX(FlipTarget,DevMarginPct*AL8))/(1+BuyerPremium),MAX(0,((AL8-AM8-MAX(FlipTarget,DevMarginPct*AL8))-N(Deals!S8)-SheriffCostsFromBid)/(BuyerPremium+RTTPurchase)))))
A9: =IF(Deals!A9="","",Deals!A9) | B9: =IF(A9="","",Deals!B9) | C9: =IF(A9="","",IF(MAX(V9,AF9)<=0,"Pass",IF(V9>=AF9,"Flip","Value-add hold"))) | D9: =IF(A9="","",MAX(V9,AF9)) | E9: =IF(A9="","",IF(D9<=0,"Pass",IF(N(Deals!D9)<=1,"$1 = awaiting minimum bid; re-check the morning of Nov 3",IF(D9<Deals!D9,"Max bid below opening bid: pass","Room of "&TEXT(D9-Deals!D9,"$#,##0")&" over opening bid")))) | F9: =IF(A9="","",IF(C9="Flip",W9,IF(C9="Value-add hold",AG9,0))) | G9: =IF(A9="","",IF(C9="Flip",TEXT(X9,"$#,##0")&" profit, "&TEXT(Y9,"0%")&"/yr over "&TEXT(M9,"0")&" mo",IF(C9="Value-add hold",TEXT(AH9,"0.0%")&" yield on cost; "&IF(ISNUMBER(AJ9),TEXT(AJ9,"0.0%")&" cash-on-cash after refi","all cash out at refi"),""))) | H9: =IF(A9="","",IF(C9="Flip",IF(W9<=FlipCeiling,"In $300k flip box","Over flip ceiling: needs to be exceptional"),IF(C9="Value-add hold","Value-add",""))) | I9: =IF(A9="","",TRIM(IF(AK9>D9,"Wholesale assignment supports "&TEXT(AK9,"$#,##0")&". ","")&IF(AND(ISNUMBER(AN9),N(AN9)>D9),"Teardown/new units supports "&TEXT(AN9,"$#,##0")&".",""))) | J9: =IF(A9="","",TRIM(IF(Deals!F9="2nd","Plaintiff is 2nd: add senior mortgage to surviving liens. ",IF(Deals!F9<>"1st","Lien position unconfirmed. ",""))&IF(N(Deals!M9)=0,"No ARV yet. ","")&IF(N(Deals!G9)=0,"No building sf: rehab is allowance only. ","")&IF(AND(N(Deals!S9)>0,D9>0,D9*(1-RTTPurchase)-SheriffCostsFromBid<N(Deals!S9)),"City claims not fully paid at max bid; unpaid part is counted as cost. ","")&IF(K9=1,"Occupancy assumed: +"&TEXT(EjectMonths,"0")&" mo and possession cost. ",""))) | K9: =IF(A9="","",IF(OR(Deals!Q9="Occupied",AND(Deals!Q9<>"Vacant",UnknownAsOccupied="Y")),1,0)) | L9: =IF(A9="","",IFERROR(INDEX(ScopeMonths,MATCH(Deals!O9,ScopeNames,0)),INDEX(ScopeMonths,3))) | M9: =IF(A9="","",DeedMonths+K9*EjectMonths+L9+SellMonths) | N9: =IF(A9="","",DeedMonths+K9*EjectMonths+L9+LeaseUpMonths) | O9: =IF(A9="","",N(Deals!G9)*IFERROR(INDEX(ScopePSF,MATCH(Deals!O9,ScopeNames,0)),INDEX(ScopePSF,3))*(1+Contingency)+BlindAllowance+N(Deals!P9)) | P9: =IF(A9="","",IF(N(Deals!K9)>0,Deals!K9,N(Deals!M9))*TaxRate/12+VacantInsMo+SecuringMo+UtilitiesMo+N(Deals!T9)) | Q9: =IF(A9="","",SheriffFees+PurchaseTitle+CompelDeedLegal+K9*PossessionCost+N(Deals!R9)+N(Deals!T9)*HOAArrearsMonths) | R9: =IF(A9="","",N(Deals!M9)*(BrokerPct+SellerRTT+SellClosingPct+ConcessionsPct)) | S9: =IF(A9="","",Q9+O9+P9*M9) | T9: =IF(A9="","",N(Deals!M9)-R9-S9) | U9: =IF(A9="","",MIN(T9-FlipTarget,(T9-FlipMinAnnROI*M9/12*S9)/(1+FlipMinAnnROI*M9/12))) | V9: =IF(A9="","",IF(N(Deals!S9)=0,MAX(0,(U9)/(1+BuyerPremium)),IF((U9)>=(N(Deals!S9)+SheriffCostsFromBid)/(1-RTTPurchase)*(1+BuyerPremium),(U9)/(1+BuyerPremium),MAX(0,((U9)-N(Deals!S9)-SheriffCostsFromBid)/(BuyerPremium+RTTPurchase))))) | W9: =IF(A9="","",((V9)*(1+BuyerPremium)+IF(N(Deals!S9)=0,0,MIN(N(Deals!S9),MAX(0,N(Deals!S9)+SheriffCostsFromBid-(V9)*(1-RTTPurchase)))))+S9) | X9: =IF(A9="","",T9-((V9)*(1+BuyerPremium)+IF(N(Deals!S9)=0,0,MIN(N(Deals!S9),MAX(0,N(Deals!S9)+SheriffCostsFromBid-(V9)*(1-RTTPurchase)))))) | Y9: =IF(A9="","",IFERROR(X9/W9/(M9/12),0)) | Z9: =IF(A9="","",N(Deals!N9)*12*(1-Vacancy)*(1-MgmtPct-MaintPct-CapexPct)-N(Deals!M9)*TaxRate-MAX(1,N(Deals!J9))*(InsPerUnit+WaterPerUnit)-N(Deals!T9)*12) | AA9: =IF(A9="","",Q9+O9+P9*N9) | AB9: =IF(A9="","",MAX(0,MIN(RefiLTV*N(Deals!M9),Z9/(RefiDSCR*12*PMT(RefiRate/12,RefiTerm*12,-1))))) | AC9: =IF(A9="","",Z9-AB9*12*PMT(RefiRate/12,RefiTerm*12,-1)) | AD9: =IF(A9="","",IF(N(Deals!S9)=0,MAX(0,(Z9/HoldTarget-AA9)/(1+BuyerPremium)),IF((Z9/HoldTarget-AA9)>=(N(Deals!S9)+SheriffCostsFromBid)/(1-RTTPurchase)*(1+BuyerPremium),(Z9/HoldTarget-AA9)/(1+BuyerPremium),MAX(0,((Z9/HoldTarget-AA9)-N(Deals!S9)-SheriffCostsFromBid)/(BuyerPremium+RTTPurchase))))) | AE9: =IF(A9="","",IF(AC9<=0,0,IF(N(Deals!S9)=0,MAX(0,(AC9/HoldTarget+AB9*(1-RefiCostPct)-AA9)/(1+BuyerPremium)),IF((AC9/HoldTarget+AB9*(1-RefiCostPct)-AA9)>=(N(Deals!S9)+SheriffCostsFromBid)/(1-RTTPurchase)*(1+BuyerPremium),(AC9/HoldTarget+AB9*(1-RefiCostPct)-AA9)/(1+BuyerPremium),MAX(0,((AC9/HoldTarget+AB9*(1-RefiCostPct)-AA9)-N(Deals!S9)-SheriffCostsFromBid)/(BuyerPremium+RTTPurchase)))))) | AF9: =IF(A9="","",IF(HoldMeasure="Cash-on-cash",AE9,AD9)) | AG9: =IF(A9="","",((AF9)*(1+BuyerPremium)+IF(N(Deals!S9)=0,0,MIN(N(Deals!S9),MAX(0,N(Deals!S9)+SheriffCostsFromBid-(AF9)*(1-RTTPurchase)))))+AA9) | AH9: =IF(A9="","",IFERROR(Z9/AG9,0)) | AI9: =IF(A9="","",AG9-AB9*(1-RefiCostPct)) | AJ9: =IF(A9="","",IF(AI9<=0,"All cash out",AC9/AI9)) | AK9: =IF(A9="","",IF(N(Deals!S9)=0,MAX(0,(T9-BuyerMarginPct*N(Deals!M9)-WholesaleMinFee)/(1+BuyerPremium)),IF((T9-BuyerMarginPct*N(Deals!M9)-WholesaleMinFee)>=(N(Deals!S9)+SheriffCostsFromBid)/(1-RTTPurchase)*(1+BuyerPremium),(T9-BuyerMarginPct*N(Deals!M9)-WholesaleMinFee)/(1+BuyerPremium),MAX(0,((T9-BuyerMarginPct*N(Deals!M9)-WholesaleMinFee)-N(Deals!S9)-SheriffCostsFromBid)/(BuyerPremium+RTTPurchase))))) | AL9: =IF(OR(A9="",N(Deals!U9)=0),"",Deals!U9*N(Deals!W9)) | AM9: =IF(AL9="","",DemoCost+N(Deals!V9)*BuildCostPSF*(1+SoftCostPct)+P9*(DeedMonths+K9*EjectMonths+BuildMonths+SellMonths)+Q9+AL9*(BrokerPct+SellerRTT+SellClosingPct+ConcessionsPct)) | AN9: =IF(AL9="","",IF(N(Deals!S9)=0,MAX(0,(AL9-AM9-MAX(FlipTarget,DevMarginPct*AL9))/(1+BuyerPremium)),IF((AL9-AM9-MAX(FlipTarget,DevMarginPct*AL9))>=(N(Deals!S9)+SheriffCostsFromBid)/(1-RTTPurchase)*(1+BuyerPremium),(AL9-AM9-MAX(FlipTarget,DevMarginPct*AL9))/(1+BuyerPremium),MAX(0,((AL9-AM9-MAX(FlipTarget,DevMarginPct*AL9))-N(Deals!S9)-SheriffCostsFromBid)/(BuyerPremium+RTTPurchase)))))
A10: =IF(Deals!A10="","",Deals!A10) | B10: =IF(A10="","",Deals!B10) | C10: =IF(A10="","",IF(MAX(V10,AF10)<=0,"Pass",IF(V10>=AF10,"Flip","Value-add hold"))) | D10: =IF(A10="","",MAX(V10,AF10)) | E10: =IF(A10="","",IF(D10<=0,"Pass",IF(N(Deals!D10)<=1,"$1 = awaiting minimum bid; re-check the morning of Nov 3",IF(D10<Deals!D10,"Max bid below opening bid: pass","Room of "&TEXT(D10-Deals!D10,"$#,##0")&" over opening bid")))) | F10: =IF(A10="","",IF(C10="Flip",W10,IF(C10="Value-add hold",AG10,0))) | G10: =IF(A10="","",IF(C10="Flip",TEXT(X10,"$#,##0")&" profit, "&TEXT(Y10,"0%")&"/yr over "&TEXT(M10,"0")&" mo",IF(C10="Value-add hold",TEXT(AH10,"0.0%")&" yield on cost; "&IF(ISNUMBER(AJ10),TEXT(AJ10,"0.0%")&" cash-on-cash after refi","all cash out at refi"),""))) | H10: =IF(A10="","",IF(C10="Flip",IF(W10<=FlipCeiling,"In $300k flip box","Over flip ceiling: needs to be exceptional"),IF(C10="Value-add hold","Value-add",""))) | I10: =IF(A10="","",TRIM(IF(AK10>D10,"Wholesale assignment supports "&TEXT(AK10,"$#,##0")&". ","")&IF(AND(ISNUMBER(AN10),N(AN10)>D10),"Teardown/new units supports "&TEXT(AN10,"$#,##0")&".",""))) | J10: =IF(A10="","",TRIM(IF(Deals!F10="2nd","Plaintiff is 2nd: add senior mortgage to surviving liens. ",IF(Deals!F10<>"1st","Lien position unconfirmed. ",""))&IF(N(Deals!M10)=0,"No ARV yet. ","")&IF(N(Deals!G10)=0,"No building sf: rehab is allowance only. ","")&IF(AND(N(Deals!S10)>0,D10>0,D10*(1-RTTPurchase)-SheriffCostsFromBid<N(Deals!S10)),"City claims not fully paid at max bid; unpaid part is counted as cost. ","")&IF(K10=1,"Occupancy assumed: +"&TEXT(EjectMonths,"0")&" mo and possession cost. ",""))) | K10: =IF(A10="","",IF(OR(Deals!Q10="Occupied",AND(Deals!Q10<>"Vacant",UnknownAsOccupied="Y")),1,0)) | L10: =IF(A10="","",IFERROR(INDEX(ScopeMonths,MATCH(Deals!O10,ScopeNames,0)),INDEX(ScopeMonths,3))) | M10: =IF(A10="","",DeedMonths+K10*EjectMonths+L10+SellMonths) | N10: =IF(A10="","",DeedMonths+K10*EjectMonths+L10+LeaseUpMonths) | O10: =IF(A10="","",N(Deals!G10)*IFERROR(INDEX(ScopePSF,MATCH(Deals!O10,ScopeNames,0)),INDEX(ScopePSF,3))*(1+Contingency)+BlindAllowance+N(Deals!P10)) | P10: =IF(A10="","",IF(N(Deals!K10)>0,Deals!K10,N(Deals!M10))*TaxRate/12+VacantInsMo+SecuringMo+UtilitiesMo+N(Deals!T10)) | Q10: =IF(A10="","",SheriffFees+PurchaseTitle+CompelDeedLegal+K10*PossessionCost+N(Deals!R10)+N(Deals!T10)*HOAArrearsMonths) | R10: =IF(A10="","",N(Deals!M10)*(BrokerPct+SellerRTT+SellClosingPct+ConcessionsPct)) | S10: =IF(A10="","",Q10+O10+P10*M10) | T10: =IF(A10="","",N(Deals!M10)-R10-S10) | U10: =IF(A10="","",MIN(T10-FlipTarget,(T10-FlipMinAnnROI*M10/12*S10)/(1+FlipMinAnnROI*M10/12))) | V10: =IF(A10="","",IF(N(Deals!S10)=0,MAX(0,(U10)/(1+BuyerPremium)),IF((U10)>=(N(Deals!S10)+SheriffCostsFromBid)/(1-RTTPurchase)*(1+BuyerPremium),(U10)/(1+BuyerPremium),MAX(0,((U10)-N(Deals!S10)-SheriffCostsFromBid)/(BuyerPremium+RTTPurchase))))) | W10: =IF(A10="","",((V10)*(1+BuyerPremium)+IF(N(Deals!S10)=0,0,MIN(N(Deals!S10),MAX(0,N(Deals!S10)+SheriffCostsFromBid-(V10)*(1-RTTPurchase)))))+S10) | X10: =IF(A10="","",T10-((V10)*(1+BuyerPremium)+IF(N(Deals!S10)=0,0,MIN(N(Deals!S10),MAX(0,N(Deals!S10)+SheriffCostsFromBid-(V10)*(1-RTTPurchase)))))) | Y10: =IF(A10="","",IFERROR(X10/W10/(M10/12),0)) | Z10: =IF(A10="","",N(Deals!N10)*12*(1-Vacancy)*(1-MgmtPct-MaintPct-CapexPct)-N(Deals!M10)*TaxRate-MAX(1,N(Deals!J10))*(InsPerUnit+WaterPerUnit)-N(Deals!T10)*12) | AA10: =IF(A10="","",Q10+O10+P10*N10) | AB10: =IF(A10="","",MAX(0,MIN(RefiLTV*N(Deals!M10),Z10/(RefiDSCR*12*PMT(RefiRate/12,RefiTerm*12,-1))))) | AC10: =IF(A10="","",Z10-AB10*12*PMT(RefiRate/12,RefiTerm*12,-1)) | AD10: =IF(A10="","",IF(N(Deals!S10)=0,MAX(0,(Z10/HoldTarget-AA10)/(1+BuyerPremium)),IF((Z10/HoldTarget-AA10)>=(N(Deals!S10)+SheriffCostsFromBid)/(1-RTTPurchase)*(1+BuyerPremium),(Z10/HoldTarget-AA10)/(1+BuyerPremium),MAX(0,((Z10/HoldTarget-AA10)-N(Deals!S10)-SheriffCostsFromBid)/(BuyerPremium+RTTPurchase))))) | AE10: =IF(A10="","",IF(AC10<=0,0,IF(N(Deals!S10)=0,MAX(0,(AC10/HoldTarget+AB10*(1-RefiCostPct)-AA10)/(1+BuyerPremium)),IF((AC10/HoldTarget+AB10*(1-RefiCostPct)-AA10)>=(N(Deals!S10)+SheriffCostsFromBid)/(1-RTTPurchase)*(1+BuyerPremium),(AC10/HoldTarget+AB10*(1-RefiCostPct)-AA10)/(1+BuyerPremium),MAX(0,((AC10/HoldTarget+AB10*(1-RefiCostPct)-AA10)-N(Deals!S10)-SheriffCostsFromBid)/(BuyerPremium+RTTPurchase)))))) | AF10: =IF(A10="","",IF(HoldMeasure="Cash-on-cash",AE10,AD10)) | AG10: =IF(A10="","",((AF10)*(1+BuyerPremium)+IF(N(Deals!S10)=0,0,MIN(N(Deals!S10),MAX(0,N(Deals!S10)+SheriffCostsFromBid-(AF10)*(1-RTTPurchase)))))+AA10) | AH10: =IF(A10="","",IFERROR(Z10/AG10,0)) | AI10: =IF(A10="","",AG10-AB10*(1-RefiCostPct)) | AJ10: =IF(A10="","",IF(AI10<=0,"All cash out",AC10/AI10)) | AK10: =IF(A10="","",IF(N(Deals!S10)=0,MAX(0,(T10-BuyerMarginPct*N(Deals!M10)-WholesaleMinFee)/(1+BuyerPremium)),IF((T10-BuyerMarginPct*N(Deals!M10)-WholesaleMinFee)>=(N(Deals!S10)+SheriffCostsFromBid)/(1-RTTPurchase)*(1+BuyerPremium),(T10-BuyerMarginPct*N(Deals!M10)-WholesaleMinFee)/(1+BuyerPremium),MAX(0,((T10-BuyerMarginPct*N(Deals!M10)-WholesaleMinFee)-N(Deals!S10)-SheriffCostsFromBid)/(BuyerPremium+RTTPurchase))))) | AL10: =IF(OR(A10="",N(Deals!U10)=0),"",Deals!U10*N(Deals!W10)) | AM10: =IF(AL10="","",DemoCost+N(Deals!V10)*BuildCostPSF*(1+SoftCostPct)+P10*(DeedMonths+K10*EjectMonths+BuildMonths+SellMonths)+Q10+AL10*(BrokerPct+SellerRTT+SellClosingPct+ConcessionsPct)) | AN10: =IF(AL10="","",IF(N(Deals!S10)=0,MAX(0,(AL10-AM10-MAX(FlipTarget,DevMarginPct*AL10))/(1+BuyerPremium)),IF((AL10-AM10-MAX(FlipTarget,DevMarginPct*AL10))>=(N(Deals!S10)+SheriffCostsFromBid)/(1-RTTPurchase)*(1+BuyerPremium),(AL10-AM10-MAX(FlipTarget,DevMarginPct*AL10))/(1+BuyerPremium),MAX(0,((AL10-AM10-MAX(FlipTarget,DevMarginPct*AL10))-N(Deals!S10)-SheriffCostsFromBid)/(BuyerPremium+RTTPurchase)))))
